Workbook

Sheet Assumptions
A1: ASSUMPTIONS — Tequila Project Model
A3: Bulk Tequila
A4: Tequila stock purchase, R/month | B4: 500000
A5: Customer payment — upfront % | B5: 0.75
A6: Customer payment — on delivery % | B6: 0.25
A7: Bulk customer YoY growth (2027 vs 2026) | B7: 0.3
A8: Bulk COGS ratio (% of revenue) | B8: 0.72
A10: RTD (Checkers)
A11: Stores in Checkers PO | B11: 300
A12: SKUs (Paloma, Margarita, Spicy Margarita) | B12: 3
A13: Cases per store per SKU (initial fill) | B13: 3
A14: Initial fill volume (cases) | B14: =B11*B12*B13 -> 2700
A15: Steady-state monthly reorder (cases) | B15: 600
A16: Wholesale price per case (R) | B16: =2287000/B14 -> 847.03704
A17: Payment terms | B17: 30 days from statement
A19: RTD COGS build (% of revenue)
A20: Tequila (allocation) | B20: 0.18
A21: Packaging (cans, printing, pallets) | B21: 0.16
A22: Co-pack production | B22: 0.12
A23: Distribution (FAL) | B23: 0.04
A24: SARS Excise | B24: 0.2
A25: Total RTD COGS ratio | B25: =SUM(B20:B24) -> 0.7
A27: Operating Costs
A28: Legal & admin, R/month | B28: 10000
A30: Opening Cash
A31: Tequila deposit paid to date | B31: -547000

Sheet P&L
A1: P&L (ACCRUAL BASIS) — Tequila Project Model
C3: Already Paid | D3: 46174 | E3: 46204 | F3: 46235 | G3: 46266 | H3: 46296 | I3: 46327 | J3: 46357 | K3: 46388 | L3: 46419 | M3: 46447 | N3: 46478 | O3: 46508 | P3: 46539 | Q3: 46569 | R3: 46600 | S3: 46631 | T3: 46661 | U3: 46692 | V3: 46722 | W3: TOTAL
A5: Bulk Tequila
B6: Revenue — Fuego RTD | D6: 242000 | F6: 242000 | J6: 363000 | K6: =D6*(1+Assumptions!$B$7) -> 314600 | N6: =F6*(1+Assumptions!$B$7) -> 314600 | P6: =D6*(1+Assumptions!$B$7) -> 314600 | R6: =F6*(1+Assumptions!$B$7) -> 314600 | V6: =J6*(1+Assumptions!$B$7) -> 471900 | W6: =SUM(D6:V6) -> 2577300
B7: Revenue — Cheeky | F7: 453750 | G7: 453750 | I7: 907500 | K7: =F7*(1+Assumptions!$B$7) -> 589875 | M7: =G7*(1+Assumptions!$B$7) -> 589875 | R7: =F7*(1+Assumptions!$B$7) -> 589875 | S7: =G7*(1+Assumptions!$B$7) -> 589875 | U7: =I7*(1+Assumptions!$B$7) -> 1179750 | W7: =SUM(D7:V7) -> 5354250
B8: Revenue — Spearhead | E8: 369770 | H8: 184885 | L8: =E8*(1+Assumptions!$B$7) -> 480701 | O8: =H8*(1+Assumptions!$B$7) -> 240350.5 | Q8: =E8*(1+Assumptions!$B$7) -> 480701 | T8: =H8*(1+Assumptions!$B$7) -> 240350.5 | W8: =SUM(D8:V8) -> 1996758
B9: Revenue — Nom | O9: 200000 | S9: 250000 | V9: 300000 | W9: =SUM(D9:V9) -> 750000
B10: Total Bulk Revenue | D10: =SUM(D6:D9) -> 242000 | E10: =SUM(E6:E9) -> 369770 | F10: =SUM(F6:F9) -> 695750 | G10: =SUM(G6:G9) -> 453750 | H10: =SUM(H6:H9) -> 184885 | I10: =SUM(I6:I9) -> 907500 | J10: =SUM(J6:J9) -> 363000 | K10: =SUM(K6:K9) -> 904475 | ... V10: =SUM(V6:V9) -> 771900 | W10: =SUM(D10:V10) -> 10678308
B11: Bulk COGS | D11: =-D10*Assumptions!$B$8 -> -174240 | E11: =-E10*Assumptions!$B$8 -> -266234.4 | F11: =-F10*Assumptions!$B$8 -> -500940 | G11: =-G10*Assumptions!$B$8 -> -326700 | H11: =-H10*Assumptions!$B$8 -> -133117.2 | I11: =-I10*Assumptions!$B$8 -> -653400 | J11: =-J10*Assumptions!$B$8 -> -261360 | K11: =-K10*Assumptions!$B$8 -> -651222 | ... V11: =-V10*Assumptions!$B$8 -> -555768 | W11: =SUM(D11:V11) -> -7688381.8
B12: Bulk Gross Margin | D12: =D10+D11 -> 67760 | E12: =E10+E11 -> 103535.6 | F12: =F10+F11 -> 194810 | G12: =G10+G11 -> 127050 | H12: =H10+H11 -> 51767.8 | I12: =I10+I11 -> 254100 | J12: =J10+J11 -> 101640 | K12: =K10+K11 -> 253253 | ... V12: =V10+V11 -> 216132 | W12: =SUM(D12:V12) -> 2989926.2
B13: Bulk Gross Margin % | D13: =IFERROR(D12/D10,0) -> 0.28 | E13: =IFERROR(E12/E10,0) -> 0.28 | F13: =IFERROR(F12/F10,0) -> 0.28 | G13: =IFERROR(G12/G10,0) -> 0.28 | H13: =IFERROR(H12/H10,0) -> 0.28 | I13: =IFERROR(I12/I10,0) -> 0.28 | J13: =IFERROR(J12/J10,0) -> 0.28 | K13: =IFERROR(K12/K10,0) -> 0.28 | ... W13: =IFERROR(W12/W10,0) -> 0.28
A15: RTD (Checkers)
B16: Cases delivered | F16: =Assumptions!$B$14 -> 2700 | H16: 1050 | I16: =Assumptions!$B$15 -> 600 | J16: =Assumptions!$B$15 -> 600 | K16: =Assumptions!$B$15 -> 600 | L16: =Assumptions!$B$15 -> 600 | M16: =Assumptions!$B$15 -> 600 | N16: =Assumptions!$B$15 -> 600 | O16: =Assumptions!$B$15 -> 600 | P16: =Assumptions!$B$15 -> 600 | ... V16: =Assumptions!$B$15 -> 600 | W16: =SUM(D16:V16) -> 12150
B17: Revenue — Checkers | D17: =D16*Assumptions!$B$16 -> 0 | E17: =E16*Assumptions!$B$16 -> 0 | F17: =F16*Assumptions!$B$16 -> 2287000 | G17: =G16*Assumptions!$B$16 -> 0 | H17: =H16*Assumptions!$B$16 -> 889388.89 | I17: =I16*Assumptions!$B$16 -> 508222.22 | J17: =J16*Assumptions!$B$16 -> 508222.22 | K17: =K16*Assumptions!$B$16 -> 508222.22 | ... V17: =V16*Assumptions!$B$16 -> 508222.22 | W17: =SUM(D17:V17) -> 10291500
B18: COGS — Tequila | D18: =-D$17*Assumptions!$B$20 -> 0 | E18: =-E$17*Assumptions!$B$20 -> 0 | F18: =-F$17*Assumptions!$B$20 -> -411660 | G18: =-G$17*Assumptions!$B$20 -> 0 | H18: =-H$17*Assumptions!$B$20 -> -160090 | I18: =-I$17*Assumptions!$B$20 -> -91480 | J18: =-J$17*Assumptions!$B$20 -> -91480 | K18: =-K$17*Assumptions!$B$20 -> -91480 | ... V18: =-V$17*Assumptions!$B$20 -> -91480 | W18: =SUM(D18:V18) -> -1852470
B19: COGS — Packaging | D19: =-D$17*Assumptions!$B$21 -> 0 | E19: =-E$17*Assumptions!$B$21 -> 0 | F19: =-F$17*Assumptions!$B$21 -> -365920 | G19: =-G$17*Assumptions!$B$21 -> 0 | H19: =-H$17*Assumptions!$B$21 -> -142302.22 | I19: =-I$17*Assumptions!$B$21 -> -81315.556 | J19: =-J$17*Assumptions!$B$21 -> -81315.556 | K19: =-K$17*Assumptions!$B$21 -> -81315.556 | ... V19: =-V$17*Assumptions!$B$21 -> -81315.556 | W19: =SUM(D19:V19) -> -1646640
B20: COGS — Production | D20: =-D$17*Assumptions!$B$22 -> 0 | E20: =-E$17*Assumptions!$B$22 -> 0 | F20: =-F$17*Assumptions!$B$22 -> -274440 | G20: =-G$17*Assumptions!$B$22 -> 0 | H20: =-H$17*Assumptions!$B$22 -> -106726.67 | I20: =-I$17*Assumptions!$B$22 -> -60986.667 | J20: =-J$17*Assumptions!$B$22 -> -60986.667 | K20: =-K$17*Assumptions!$B$22 -> -60986.667 | ... V20: =-V$17*Assumptions!$B$22 -> -60986.667 | W20: =SUM(D20:V20) -> -1234980
B21: COGS — Distribution | D21: =-D$17*Assumptions!$B$23 -> 0 | E21: =-E$17*Assumptions!$B$23 -> 0 | F21: =-F$17*Assumptions!$B$23 -> -91480 | G21: =-G$17*Assumptions!$B$23 -> 0 | H21: =-H$17*Assumptions!$B$23 -> -35575.556 | I21: =-I$17*Assumptions!$B$23 -> -20328.889 | J21: =-J$17*Assumptions!$B$23 -> -20328.889 | K21: =-K$17*Assumptions!$B$23 -> -20328.889 | ... V21: =-V$17*Assumptions!$B$23 -> -20328.889 | W21: =SUM(D21:V21) -> -411660
B22: COGS — Excise | D22: =-D$17*Assumptions!$B$24 -> 0 | E22: =-E$17*Assumptions!$B$24 -> 0 | F22: =-F$17*Assumptions!$B$24 -> -457400 | G22: =-G$17*Assumptions!$B$24 -> 0 | H22: =-H$17*Assumptions!$B$24 -> -177877.78 | I22: =-I$17*Assumptions!$B$24 -> -101644.44 | J22: =-J$17*Assumptions!$B$24 -> -101644.44 | K22: =-K$17*Assumptions!$B$24 -> -101644.44 | ... V22: =-V$17*Assumptions!$B$24 -> -101644.44 | W22: =SUM(D22:V22) -> -2058300
B23: Total RTD COGS | D23: =SUM(D18:D22) -> 0 | E23: =SUM(E18:E22) -> 0 | F23: =SUM(F18:F22) -> -1600900 | G23: =SUM(G18:G22) -> 0 | H23: =SUM(H18:H22) -> -622572.22 | I23: =SUM(I18:I22) -> -355755.56 | J23: =SUM(J18:J22) -> -355755.56 | K23: =SUM(K18:K22) -> -355755.56 | ... V23: =SUM(V18:V22) -> -355755.56 | W23: =SUM(D23:V23) -> -7204050
B24: RTD Gross Margin | D24: =D17+D23 -> 0 | E24: =E17+E23 -> 0 | F24: =F17+F23 -> 686100 | G24: =G17+G23 -> 0 | H24: =H17+H23 -> 266816.67 | I24: =I17+I23 -> 152466.67 | J24: =J17+J23 -> 152466.67 | K24: =K17+K23 -> 152466.67 | ... V24: =V17+V23 -> 152466.67 | W24: =SUM(D24:V24) -> 3087450
B25: RTD Gross Margin % | D25: =IFERROR(D24/D17,0) -> 0 | E25: =IFERROR(E24/E17,0) -> 0 | F25: =IFERROR(F24/F17,0) -> 0.3 | G25: =IFERROR(G24/G17,0) -> 0 | H25: =IFERROR(H24/H17,0) -> 0.3 | I25: =IFERROR(I24/I17,0) -> 0.3 | J25: =IFERROR(J24/J17,0) -> 0.3 | K25: =IFERROR(K24/K17,0) -> 0.3 | ... W25: =IFERROR(W24/W17,0) -> 0.3
A27: Combined
B28: Total Revenue | D28: =D10+D17 -> 242000 | E28: =E10+E17 -> 369770 | F28: =F10+F17 -> 2982750 | G28: =G10+G17 -> 453750 | H28: =H10+H17 -> 1074273.9 | I28: =I10+I17 -> 1415722.2 | J28: =J10+J17 -> 871222.22 | K28: =K10+K17 -> 1412697.2 | ... V28: =V10+V17 -> 1280122.2 | W28: =SUM(D28:V28) -> 20969808
B29: Total COGS | D29: =D11+D23 -> -174240 | E29: =E11+E23 -> -266234.4 | F29: =F11+F23 -> -2101840 | G29: =G11+G23 -> -326700 | H29: =H11+H23 -> -755689.42 | I29: =I11+I23 -> -1009155.6 | J29: =J11+J23 -> -617115.56 | K29: =K11+K23 -> -1006977.6 | ... V29: =V11+V23 -> -911523.56 | W29: =SUM(D29:V29) -> -14892432
B30: Total Gross Margin | D30: =D12+D24 -> 67760 | E30: =E12+E24 -> 103535.6 | F30: =F12+F24 -> 880910 | G30: =G12+G24 -> 127050 | H30: =H12+H24 -> 318584.47 | I30: =I12+I24 -> 406566.67 | J30: =J12+J24 -> 254106.67 | K30: =K12+K24 -> 405719.67 | ... V30: =V12+V24 -> 368598.67 | W30: =SUM(D30:V30) -> 6077376.2
B31: Gross Margin % | D31: =IFERROR(D30/D28,0) -> 0.28 | E31: =IFERROR(E30/E28,0) -> 0.28 | F31: =IFERROR(F30/F28,0) -> 0.29533484 | G31: =IFERROR(G30/G28,0) -> 0.28 | H31: =IFERROR(H30/H28,0) -> 0.29655795 | I31: =IFERROR(I30/I28,0) -> 0.28717969 | J31: =IFERROR(J30/J28,0) -> 0.29166688 | K31: =IFERROR(K30/K28,0) -> 0.28719506 | ... W31: =IFERROR(W30/W28,0) -> 0.28981554
B32: Operating Costs (Legal/admin) | D32: =-Assumptions!$B$28 -> -10000 | E32: =-Assumptions!$B$28 -> -10000 | F32: =-Assumptions!$B$28 -> -10000 | G32: =-Assumptions!$B$28 -> -10000 | H32: =-Assumptions!$B$28 -> -10000 | I32: =-Assumptions!$B$28 -> -10000 | J32: =-Assumptions!$B$28 -> -10000 | K32: =-Assumptions!$B$28 -> -10000 | ... V32: =-Assumptions!$B$28 -> -10000 | W32: =SUM(D32:V32) -> -190000
B33: EBITDA | D33: =D30+D32 -> 57760 | E33: =E30+E32 -> 93535.6 | F33: =F30+F32 -> 870910 | G33: =G30+G32 -> 117050 | H33: =H30+H32 -> 308584.47 | I33: =I30+I32 -> 396566.67 | J33: =J30+J32 -> 244106.67 | K33: =K30+K32 -> 395719.67 | ... V33: =V30+V32 -> 358598.67 | W33: =SUM(D33:V33) -> 5887376.2
B34: EBITDA Margin % | D34: =IFERROR(D33/D28,0) -> 0.23867769 | E34: =IFERROR(E33/E28,0) -> 0.25295616 | F34: =IFERROR(F33/F28,0) -> 0.29198223 | G34: =IFERROR(G33/G28,0) -> 0.25796143 | H34: =IFERROR(H33/H28,0) -> 0.28724934 | I34: =IFERROR(I33/I28,0) -> 0.28011616 | J34: =IFERROR(J33/J28,0) -> 0.28018875 | K34: =IFERROR(K33/K28,0) -> 0.2801164 | ... W34: =IFERROR(W33/W28,0) -> 0.28075489

Sheet Cashflow
A1: CASHFLOW (CASH BASIS) — Tequila Project Model
C3: Already Paid | D3: 46174 | E3: 46204 | F3: 46235 | G3: 46266 | H3: 46296 | I3: 46327 | J3: 46357 | K3: 46388 | L3: 46419 | M3: 46447 | N3: 46478 | O3: 46508 | P3: 46539 | Q3: 46569 | R3: 46600 | S3: 46631 | T3: 46661 | U3: 46692 | V3: 46722 | W3: TOTAL
A5: Bulk Tequila
B6: Receipts — 75% upfront (1 mo before delivery) | C6: =Assumptions!$B$5*'P&L'!D10 -> 181500 | D6: =Assumptions!$B$5*'P&L'!E10 -> 277327.5 | E6: =Assumptions!$B$5*'P&L'!F10 -> 521812.5 | F6: =Assumptions!$B$5*'P&L'!G10 -> 340312.5 | G6: =Assumptions!$B$5*'P&L'!H10 -> 138663.75 | H6: =Assumptions!$B$5*'P&L'!I10 -> 680625 | I6: =Assumptions!$B$5*'P&L'!J10 -> 272250 | J6: =Assumptions!$B$5*'P&L'!K10 -> 678356.25 | ... U6: =Assumptions!$B$5*'P&L'!V10 -> 578925 | V6: 0 | W6: =SUM(C6:V6) -> 8008731
B7: Receipts — 25% on delivery | D7: =Assumptions!$B$6*'P&L'!D10 -> 60500 | E7: =Assumptions!$B$6*'P&L'!E10 -> 92442.5 | F7: =Assumptions!$B$6*'P&L'!F10 -> 173937.5 | G7: =Assumptions!$B$6*'P&L'!G10 -> 113437.5 | H7: =Assumptions!$B$6*'P&L'!H10 -> 46221.25 | I7: =Assumptions!$B$6*'P&L'!I10 -> 226875 | J7: =Assumptions!$B$6*'P&L'!J10 -> 90750 | K7: =Assumptions!$B$6*'P&L'!K10 -> 226118.75 | ... V7: =Assumptions!$B$6*'P&L'!V10 -> 192975 | W7: =SUM(C7:V7) -> 2669577
B8: Total bulk receipts | C8: =C6+C7 -> 181500 | D8: =D6+D7 -> 337827.5 | E8: =E6+E7 -> 614255 | F8: =F6+F7 -> 514250 | G8: =G6+G7 -> 252101.25 | H8: =H6+H7 -> 726846.25 | I8: =I6+I7 -> 499125 | J8: =J6+J7 -> 769106.25 | ... V8: =V6+V7 -> 192975 | W8: =SUM(C8:V8) -> 10678308
B9: Tequila stock purchases | C9: 0 | D9: -315000 | E9: -500000 | F9: -500000 | G9: -500000 | H9: -500000 | I9: 0 | J9: 0 | K9: =-Assumptions!$B$4 -> -500000 | L9: =-Assumptions!$B$4 -> -500000 | M9: =-Assumptions!$B$4 -> -500000 | N9: =-Assumptions!$B$4 -> -500000 | O9: =-Assumptions!$B$4 -> -500000 | P9: =-Assumptions!$B$4 -> -500000 | Q9: =-Assumptions!$B$4 -> -500000 | R9: =-Assumptions!$B$4 -> -500000 | ... V9: =-Assumptions!$B$4 -> -500000 | W9: =SUM(C9:V9) -> -8315000
B10: Net bulk cashflow | C10: =C8+C9 -> 181500 | D10: =D8+D9 -> 22827.5 | E10: =E8+E9 -> 114255 | F10: =F8+F9 -> 14250 | G10: =G8+G9 -> -247898.75 | H10: =H8+H9 -> 226846.25 | I10: =I8+I9 -> 499125 | J10: =J8+J9 -> 769106.25 | ... V10: =V8+V9 -> -307025 | W10: =SUM(C10:V10) -> 2363308
A12: RTD (Checkers)
B13: Checkers receipts (+30 days) | C13: 0 | D13: ='P&L'!C17 -> 0 | E13: ='P&L'!D17 -> 0 | F13: ='P&L'!E17 -> 0 | G13: ='P&L'!F17 -> 2287000 | H13: ='P&L'!G17 -> 0 | I13: ='P&L'!H17 -> 889388.89 | J13: ='P&L'!I17 -> 508222.22 | K13: ='P&L'!J17 -> 508222.22 | ... V13: ='P&L'!U17 -> 508222.22 | W13: =SUM(C13:V13) -> 9783277.8
B14: Bron Pro | D14: -103500 | F14: -243800 | W14: =SUM(C14:V14) -> -347300
B15: Sullwaldt printing | E15: -91066 | H15: -72400 | W15: =SUM(C15:V15) -> -163466
B16: Tiny Keg cans | E16: -405950 | G16: -319000 | W16: =SUM(C16:V16) -> -724950
B17: Chep pallets | D17: -14375 | W17: =SUM(C17:V17) -> -14375
B18: FAL distribution | E18: -51750 | H18: -28000 | W18: =SUM(C18:V18) -> -79750
B19: Tiny Keg production | F19: -373350 | G19: -293250 | W19: =SUM(C19:V19) -> -666600
B20: SARS Excise | G20: -630000 | I20: -495571 | W20: =SUM(C20:V20) -> -1125571
B21: Legal/admin | E21: -57500 | K21: =-Assumptions!$B$28 -> -10000 | L21: =-Assumptions!$B$28 -> -10000 | M21: =-Assumptions!$B$28 -> -10000 | N21: =-Assumptions!$B$28 -> -10000 | O21: =-Assumptions!$B$28 -> -10000 | P21: =-Assumptions!$B$28 -> -10000 | Q21: =-Assumptions!$B$28 -> -10000 | R21: =-Assumptions!$B$28 -> -10000 | ... V21: =-Assumptions!$B$28 -> -10000 | W21: =SUM(C21:V21) -> -177500
B22: Recurring RTD COGS (2027 ex-tequila) | K22: =-Assumptions!$B$15*Assumptions!$B$16*(Assumptions!$B$25-Assumptions!$B$20) -> -264275.56 | L22: =-Assumptions!$B$15*Assumptions!$B$16*(Assumptions!$B$25-Assumptions!$B$20) -> -264275.56 | M22: =-Assumptions!$B$15*Assumptions!$B$16*(Assumptions!$B$25-Assumptions!$B$20) -> -264275.56 | N22: =-Assumptions!$B$15*Assumptions!$B$16*(Assumptions!$B$25-Assumptions!$B$20) -> -264275.56 | O22: =-Assumptions!$B$15*Assumptions!$B$16*(Assumptions!$B$25-Assumptions!$B$20) -> -264275.56 | P22: =-Assumptions!$B$15*Assumptions!$B$16*(Assumptions!$B$25-Assumptions!$B$20) -> -264275.56 | Q22: =-Assumptions!$B$15*Assumptions!$B$16*(Assumptions!$B$25-Assumptions!$B$20) -> -264275.56 | R22: =-Assumptions!$B$15*Assumptions!$B$16*(Assumptions!$B$25-Assumptions!$B$20) -> -264275.56 | ... V22: =-Assumptions!$B$15*Assumptions!$B$16*(Assumptions!$B$25-Assumptions!$B$20) -> -264275.56 | W22: =SUM(C22:V22) -> -3171306.7
B23: Total RTD payments | C23: =SUM(C14:C22) -> 0 | D23: =SUM(D14:D22) -> -117875 | E23: =SUM(E14:E22) -> -606266 | F23: =SUM(F14:F22) -> -617150 | G23: =SUM(G14:G22) -> -1242250 | H23: =SUM(H14:H22) -> -100400 | I23: =SUM(I14:I22) -> -495571 | J23: =SUM(J14:J22) -> 0 | ... V23: =SUM(V14:V22) -> -274275.56 | W23: =SUM(C23:V23) -> -6470818.7
B24: Net RTD cashflow | C24: =C13+C23 -> 0 | D24: =D13+D23 -> -117875 | E24: =E13+E23 -> -606266 | F24: =F13+F23 -> -617150 | G24: =G13+G23 -> 1044750 | H24: =H13+H23 -> -100400 | I24: =I13+I23 -> 393817.89 | J24: =J13+J23 -> 508222.22 | ... V24: =V13+V23 -> 233946.67 | W24: =SUM(C24:V24) -> 3312459.1
A26: Combined | B26: Combined monthly net cashflow | C26: =C10+C24 -> 181500 | D26: =D10+D24 -> -95047.5 | E26: =E10+E24 -> -492011 | F26: =F10+F24 -> -602900 | G26: =G10+G24 -> 796851.25 | H26: =H10+H24 -> 126446.25 | I26: =I10+I24 -> 892942.89 | J26: =J10+J24 -> 1277328.5 | ... V26: =V10+V24 -> -73078.333 | W26: =SUM(C26:V26) -> 5675767.1
B27: Cumulative cash position | C27: =Assumptions!$B$31+C26 -> -365500 | D27: =C27+D26 -> -460547.5 | E27: =D27+E26 -> -952558.5 | F27: =E27+F26 -> -1555458.5 | G27: =F27+G26 -> -758607.25 | H27: =G27+H26 -> -632161 | I27: =H27+I26 -> 260781.89 | J27: =I27+J26 -> 1538110.4 | K27: =J27+K26 -> 1858701.5 | ... V27: =U27+V26 -> 5128767.1 | W27: =V27 -> 5128767.1

Sheet Summary
A1: SUMMARY — Tequila Project Model
A3: P&L Outputs (Jun 26 — Dec 27)
A4: Total revenue | B4: ='P&L'!W28 -> 20969808
A5: Total gross margin | B5: ='P&L'!W30 -> 6077376.2
A6: Gross margin % | B6: ='P&L'!W31 -> 0.28981554
A7: Total EBITDA | B7: ='P&L'!W33 -> 5887376.2
A8: EBITDA margin % | B8: ='P&L'!W34 -> 0.28075489
A10: Cashflow
A11: Peak funding requirement | B11: =MIN(Cashflow!C27:V27) -> -1555458.5
A12: Month of peak funding | B12: =INDEX(Cashflow!$C$3:$V$3,MATCH(MIN(Cashflow!$C$27:$V$27),Cashflow!$C$27:$V$27,0)) -> 46235
A13: Ending cash position (Dec 27) | B13: =Cashflow!V27 -> 5128767.1
A14: Net cashflow over period | B14: =Cashflow!W26 -> 5675767.1
A16: Outstanding Receivables at Dec 27
A17: Checkers (Dec 27 RTD sale, paid Jan 28) | B17: ='P&L'!V17 -> 508222.22

Sheet Valuation
A1: VALUATION — Tequila Project Model
A3: Key Operating Metrics (linked to model) | B3: 2026 (Jun–Dec) | C3: 2027 (Full Year) | D3: Total Period
A4: Total Revenue | B4: =SUM('P&L'!D28:J28) -> 7409488.3 | C4: =SUM('P&L'!K28:V28) -> 13560320 | D4: ='P&L'!W28 -> 20969808
A5: Gross Margin | B5: =SUM('P&L'!D30:J30) -> 2158513.4 | C5: =SUM('P&L'!K30:V30) -> 3918862.8 | D5: ='P&L'!W30 -> 6077376.2
A6: Gross Margin % | B6: =IFERROR(B5/B4,0) -> 0.29131747 | C6: =IFERROR(C5/C4,0) -> 0.28899487 | D6: =IFERROR(D5/D4,0) -> 0.28981554
A7: EBITDA | B7: =SUM('P&L'!D33:J33) -> 2088513.4 | C7: =SUM('P&L'!K33:V33) -> 3798862.8 | D7: ='P&L'!W33 -> 5887376.2
A8: EBITDA Margin % | B8: =IFERROR(B7/B4,0) -> 0.28187012 | C8: =IFERROR(C7/C4,0) -> 0.28014552 | D8: =IFERROR(D7/D4,0) -> 0.28075489
A10: Run-rate (H2-2027 annualised) | B10: Revenue | C10: EBITDA | D10: EBITDA %
A11: Run-rate (last 6mo × 2) | B11: =SUM('P&L'!Q28:V28)*2 -> 14932770 | C11: =SUM('P&L'!Q33:V33)*2 -> 4183148.8 | D11: =IFERROR(C11/B11,0) -> 0.28013215
A13: Method 1: EBITDA Multiple (applied to 2027 EBITDA) | B13: Low | C13: Base | D13: High
A14: EV / EBITDA multiple | B14: 6 | C14: 9 | D14: 12
A15: 2027 EBITDA | B15: =$C$7 -> 3798862.8 | C15: =$C$7 -> 3798862.8 | D15: =$C$7 -> 3798862.8
A16: Enterprise Value | B16: =B14*B15 -> 22793177 | C16: =C14*C15 -> 34189766 | D16: =D14*D15 -> 45586354
A17: Note: SA premium spirits/early-stage RTD comps
A19: Method 2: Revenue Multiple (applied to 2027 Revenue) | B19: Low | C19: Base | D19: High
A20: EV / Revenue multiple | B20: 1 | C20: 1.5 | D20: 2.5
A21: 2027 Revenue | B21: =$C$4 -> 13560320 | C21: =$C$4 -> 13560320 | D21: =$C$4 -> 13560320
A22: Enterprise Value | B22: =B20*B21 -> 13560320 | C22: =C20*C21 -> 20340480 | D22: =D20*D21 -> 33900799
A23: Note: Early-stage premium spirits brands; reflects unproven scale
A25: Method 3: Simplified DCF (EBITDA proxy for cash, mid-year convention) | B25: Low | C25: Base | D25: High
A26: WACC | B26: 0.22 | C26: 0.18 | D26: 0.15
A27: Exit EBITDA multiple (end of 2027) | B27: 6 | C27: 8 | D27: 10
A28: 2026 EBITDA (H2) | B28: =$B$7 -> 2088513.4 | C28: =$B$7 -> 2088513.4 | D28: =$B$7 -> 2088513.4
A29: 2027 EBITDA (FY) | B29: =$C$7 -> 3798862.8 | C29: =$C$7 -> 3798862.8 | D29: =$C$7 -> 3798862.8
A30: Terminal Value (2027 EBITDA × exit mult.) | B30: =B29*B27 -> 22793177 | C30: =C29*C27 -> 30390903 | D30: =D29*D27 -> 37988628
A31: PV of 2026 EBITDA (discount 0.25y) | B31: =B28/(1+B26)^0.25 -> 1987226.2 | C31: =C28/(1+C26)^0.25 -> 2003857.2 | D31: =D28/(1+D26)^0.25 -> 2016799.9
A32: PV of 2027 EBITDA (discount 1.0y) | B32: =B29/(1+B26)^1 -> 3113822 | C32: =C29/(1+C26)^1 -> 3219375.3 | D32: =D29/(1+D26)^1 -> 3303359
A33: PV of Terminal Value (discount 1.5y) | B33: =B30/(1+B26)^1.5 -> 16914732 | C33: =C30/(1+C26)^1.5 -> 23709401 | D33: =D30/(1+D26)^1.5 -> 30803981
A34: Enterprise Value (DCF) | B34: =SUM(B31:B33) -> 22015780 | C34: =SUM(C31:C33) -> 28932634 | D34: =SUM(D31:D33) -> 36124140
A35: Note: EBITDA used as cash proxy (no D&A; minimal capex). WACC reflects SA early-stage spirits risk.
A37: Valuation Summary — Enterprise Value Range | B37: Low | C37: Base | D37: High
A38: EBITDA Multiple | B38: =B16 -> 22793177 | C38: =C16 -> 34189766 | D38: =D16 -> 45586354
A39: Revenue Multiple | B39: =B22 -> 13560320 | C39: =C22 -> 20340480 | D39: =D22 -> 33900799
A40: DCF | B40: =B34 -> 22015780 | C40: =C34 -> 28932634 | D40: =D34 -> 36124140
A41: Blended (avg of methods) | B41: =AVERAGE(B38:B40) -> 19456426 | C41: =AVERAGE(C38:C40) -> 27820960 | D41: =AVERAGE(D38:D40) -> 38537098
A43: Bridge to Equity Value | B43: Low | C43: Base | D43: High
A44: Enterprise Value (blended) | B44: =B41 -> 19456426 | C44: =C41 -> 27820960 | D44: =D41 -> 38537098
A45: (+) Cash today | B45: 0 | C45: =B45 -> 0 | D45: =B45 -> 0
A46: (−) Debt today | B46: 0 | C46: =B46 -> 0 | D46: =B46 -> 0
A47: Equity Value | B47: =B44+B45-B46 -> 19456426 | C47: =C44+C45-C46 -> 27820960 | D47: =D44+D45-D46 -> 38537098
...
